Workbook

Sheet Инструкция
B2: Модель TCO (Total Cost of Ownership) — кейс «Africa Delivery», горизонт 5 лет
B4: Зачем этот файл
B5: Задача | C5: Оценить полную стоимость владения выбранным архитектурным вариантом на 5 лет и использовать цифры как аргумент в ADR №1 («Выбор архитектурного стиля»).
B6: Как использовать | C6: Заполни один и тот же шаблон для каждого рассматриваемого варианта (например: модульный монолит / SOA / микросервисы) — сравнивать нужно итоги, а не ощущения.
B8: Цветовая легенда
B9: Синий текст на жёлтом фоне | C9: Ячейки для заполнения. Только их и редактируем.
B10: Чёрный текст | C10: Формулы. Не трогаем — пересчитаются сами.
B11: Зелёный текст | C11: Ссылка на лист «Допущения».
B13: Порядок работы
B14: Шаг 1 | C14: Лист «Допущения» → блок 1: вбить драйверы бизнеса по годам (активные пользователи, число заказов, средний чек). Из них считается GMV. | D14: business/product forecasting
B15: Шаг 2 | C15: Лист «Допущения» → блок 2: финансовые допущения (инфляция, рост ФОТ, ставка дисконтирования, резерв, целевой SLO). | D15: business/product forecasting
B16: Шаг 3 | C16: Лист «TCO» → в колонке «База, $/год (Год 1)» указать затраты первого года по каждой статье. Лишние статьи оставить пустыми, свои — дописать в свободные строки.
B17: Шаг 4 | C17: Лист «TCO» → в колонке «Драйвер роста» выбрать из выпадающего списка, от чего растёт статья: фикс / инфляция / ФОТ / пользователи / заказы / GMV. Годы 2–5 посчитаются сами.
B18: Шаг 5 | C18: Посмотреть блок «Ключевые метрики» внизу листа «TCO»: итог за 5 лет, NPV, стоимость на заказ, проверку бюджета CFO ($9k/мес на облако).
B20: Что важно не забыть в этом кейсе
B21: Бюджет CFO | C21: $9 000/мес на облако на старте. Если Год 1 в блоке «Облачная инфраструктура» не проходит — это архитектурное решение, а не ошибка модели: опиши, что урезаешь.
B22: Цена простоя | C22: Инвестор оценивает минуту простоя в $12 000. Целевой SLO 99,99% = 52,6 мин/год ≈ $631k. Этот риск считается отдельным блоком — сравни его со стоимостью резервирования.
B23: Транзакционные расходы | C23: Комиссии M-Pesa / Flutterwave / Paystack, SMS и WhatsApp растут с GMV и числом заказов и на горизонте 5 лет обычно обгоняют инфраструктуру. Не забудь их — это типичная ошибка.
B24: Сравнение вариантов | C24: Транзакционные расходы (блок 3) почти одинаковы для любой архитектуры — это pass-through от оборота. Варианты архитектуры сравнивай по блокам 1, 2, 4 и 6.
B25: Разовые затраты | C25: Комплаенс-аудит NDPR/POPIA, пентест, миграция — если статья возникает не каждый год, просто перезапиши формулу в нужной ячейке года числом (и покрась в синий).
B26: Люди | C26: ФОТ команды — обычно самая крупная статья TCO. Микросервисы дешевле в масштабировании, но дороже в эксплуатации: это должно быть видно в цифрах, а не только в тексте ADR.
B28: Все числа в файле — примеры для демонстрации формата. Замени их своими оценками и укажи источник в колонке «Комментарий / источник».

Sheet Допущения
B2: Допущения модели TCO — Africa Delivery
B3: Заполняются только ячейки с жёлтой заливкой. Все числа ниже — пример, заменить своими.
B5: 1. Драйверы бизнеса — заполнить
B6: Показатель | C6: Год 1 | D6: Год 2 | E6: Год 3 | F6: Год 4 | G6: Год 5 | H6: Комментарий / источник
B7: Активные пользователи (на конец года) | C7: 150000 | D7: 600000 | E7: 1500000 | F7: 2500000 | G7: 3500000 | H7: Цель кейса: 1М+ пользователей к 12 месяцам, 5 стран
B8: Число заказов в год | C8: 300000 | D8: 1800000 | E8: 6000000 | F8: 12000000 | G8: 18000000 | H8: MVP: 100 продавцов, 5000 SKU. Оценка студента
B9: Средний чек (AOV), $ | C9: 25 | D9: 26 | E9: 27 | F9: 28 | G9: 29 | H9: Оценка студента по рынку (Jumia / Takealot)
B10: GMV, $ в год (расчёт) | C10: =C8*C9 -> 7500000 | D10: =D8*D9 -> 46800000 | E10: =E8*E9 -> 162000000 | F10: =F8*F9 -> 336000000 | G10: =G8*G9 -> 522000000 | H10: Расчёт: заказы × средний чек
B12: 2. Финансовые допущения — заполнить
B13: Параметр | C13: Значение | H13: Комментарий / источник
B14: Инфляция затрат, % в год | C14: 0.08 | H14: Применяется к статьям с драйвером «инфляция»
B15: Рост ФОТ, % в год | C15: 0.12 | H15: Дефицит ИТ-специалистов на рынке — рост выше инфляции
B16: Ставка дисконтирования, % в год | C16: 0.2 | H16: Для расчёта NPV затрат. Стартап, высокий риск
B17: Резерв на непредвиденное (contingency), % | C17: 0.15 | H17: Надбавка к прямым затратам
B18: Бюджет CFO на облако, $/мес | C18: 9000 | H18: Ограничение из письма CFO
B19: Стоимость минуты простоя, $ | C19: 12000 | H19: Оценка инвестора из условия кейса
B20: Целевой SLO (доступность), % | C20: 0.9999 | H20: Mission critical: 99,99% = 52,6 мин/год
B21: Учитывать стоимость простоя в TCO (1 — да, 0 — нет) | C21: 1 | H21: Переключатель для сценарного анализа
B23: 3. Индексы роста — расчёт, не редактировать
B24: Драйвер | C24: Год 1 | D24: Год 2 | E24: Год 3 | F24: Год 4 | G24: Год 5 | H24: Как считается
B25: фикс | C25: 1 | D25: 1 | E25: 1 | F25: 1 | G25: 1 | H25: Затраты не меняются по годам
B26: инфляция | C26: 1 | D26: =C26*(1+$C$14) -> 1.08 | E26: =D26*(1+$C$14) -> 1.1664 | F26: =E26*(1+$C$14) -> 1.259712 | G26: =F26*(1+$C$14) -> 1.360489 | H26: Год N = Год N-1 × (1 + инфляция)
B27: ФОТ | C27: 1 | D27: =C27*(1+$C$15) -> 1.12 | E27: =D27*(1+$C$15) -> 1.2544 | F27: =E27*(1+$C$15) -> 1.404928 | G27: =F27*(1+$C$15) -> 1.5735194 | H27: Год N = Год N-1 × (1 + рост ФОТ)
B28: пользователи | C28: =C7/$C$7 -> 1 | D28: =D7/$C$7 -> 4 | E28: =E7/$C$7 -> 10 | F28: =F7/$C$7 -> 16.666667 | G28: =G7/$C$7 -> 23.333333 | H28: Пропорционально числу активных пользователей
B29: заказы | C29: =C8/$C$8 -> 1 | D29: =D8/$C$8 -> 6 | E29: =E8/$C$8 -> 20 | F29: =F8/$C$8 -> 40 | G29: =G8/$C$8 -> 60 | H29: Пропорционально числу заказов
B30: GMV | C30: =C10/$C$10 -> 1 | D30: =D10/$C$10 -> 6.24 | E30: =E10/$C$10 -> 21.6 | F30: =F10/$C$10 -> 44.8 | G30: =G10/$C$10 -> 69.6 | H30: Пропорционально обороту
B32: Драйвер «пользователи» — упрощение: облачные расходы редко растут строго линейно (есть эффект масштаба и обратный эффект — рост нагрузки на БД). При желании введи свой драйвер отдельной строкой в таблице индексов.

Sheet TCO-A
B2: TCO на 5 лет — Africa Delivery
B3: Заполняем колонки «Драйвер роста» и «База, $/год (Год 1)». Годы 1–5 считаются автоматически.
B5: Статья затрат | C5: Драйвер роста | D5: База, $/год (Год 1) | E5: Год 1 | F5: Год 2 | G5: Год 3 | H5: Год 4 | I5: Год 5 | J5: Итого 5 лет | K5: Доля | L5: Комментарий / источник
B6: БЛОК 1. Облачная инфраструктура (OpEx)
B7: Compute: ноды / контейнеры / serverless | C7: пользователи | D7: 18525.26 | E7: {=IF($D7="","",$D7*INDEX(Допущения!$C$25:$G$30,MATCH($C7,Допущения!$B$25:$B$30,0),1))} -> 18525.26 | F7: {=IF($D7="","",$D7*INDEX(Допущения!$C$25:$G$30,MATCH($C7,Допущения!$B$25:$B$30,0),2))} -> 74101.04 | G7: {=IF($D7="","",$D7*INDEX(Допущения!$C$25:$G$30,MATCH($C7,Допущения!$B$25:$B$30,0),3))} -> 185252.6 | H7: {=IF($D7="","",$D7*INDEX(Допущения!$C$25:$G$30,MATCH($C7,Допущения!$B$25:$B$30,0),4))} -> 308754.33 | I7: {=IF($D7="","",$D7*INDEX(Допущения!$C$25:$G$30,MATCH($C7,Допущения!$B$25:$B$30,0),5))} -> 432256.07 | J7: =SUM(E7:I7) -> 1018889.3 | L7: AWS af-south-1, оценка по калькулятору
B8: Управляемые БД (PostgreSQL, реплики) | C8: пользователи | D8: 27787.9 | E8: {=IF($D8="","",$D8*INDEX(Допущения!$C$25:$G$30,MATCH($C8,Допущения!$B$25:$B$30,0),1))} -> 27787.9 | F8: {=IF($D8="","",$D8*INDEX(Допущения!$C$25:$G$30,MATCH($C8,Допущения!$B$25:$B$30,0),2))} -> 111151.6 | G8: {=IF($D8="","",$D8*INDEX(Допущения!$C$25:$G$30,MATCH($C8,Допущения!$B$25:$B$30,0),3))} -> 277879 | H8: {=IF($D8="","",$D8*INDEX(Допущения!$C$25:$G$30,MATCH($C8,Допущения!$B$25:$B$30,0),4))} -> 463131.67 | I8: {=IF($D8="","",$D8*INDEX(Допущения!$C$25:$G$30,MATCH($C8,Допущения!$B$25:$B$30,0),5))} -> 648384.33 | J8: =SUM(E8:I8) -> 1528334.5 | L8: Managed RDS + read replica
B9: Хранилище объектов и резервные копии | C9: пользователи | D9: 1800 | E9: {=IF($D9="","",$D9*INDEX(Допущения!$C$25:$G$30,MATCH($C9,Допущения!$B$25:$B$30,0),1))} -> 1800 | F9: {=IF($D9="","",$D9*INDEX(Допущения!$C$25:$G$30,MATCH($C9,Допущения!$B$25:$B$30,0),2))} -> 7200 | G9: {=IF($D9="","",$D9*INDEX(Допущения!$C$25:$G$30,MATCH($C9,Допущения!$B$25:$B$30,0),3))} -> 18000 | H9: {=IF($D9="","",$D9*INDEX(Допущения!$C$25:$G$30,MATCH($C9,Допущения!$B$25:$B$30,0),4))} -> 30000 | I9: {=IF($D9="","",$D9*INDEX(Допущения!$C$25:$G$30,MATCH($C9,Допущения!$B$25:$B$30,0),5))} -> 42000 | J9: =SUM(E9:I9) -> 99000 | L9: Фото товаров, 5000 SKU на старте
B10: CDN и исходящий трафик | C10: пользователи | D10: 5430 | E10: {=IF($D10="","",$D10*INDEX(Допущения!$C$25:$G$30,MATCH($C10,Допущения!$B$25:$B$30,0),1))} -> 5430 | F10: {=IF($D10="","",$D10*INDEX(Допущения!$C$25:$G$30,MATCH($C10,Допущения!$B$25:$B$30,0),2))} -> 21720 | G10: {=IF($D10="","",$D10*INDEX(Допущения!$C$25:$G$30,MATCH($C10,Допущения!$B$25:$B$30,0),3))} -> 54300 | H10: {=IF($D10="","",$D10*INDEX(Допущения!$C$25:$G$30,MATCH($C10,Допущения!$B$25:$B$30,0),4))} -> 90500 | I10: {=IF($D10="","",$D10*INDEX(Допущения!$C$25:$G$30,MATCH($C10,Допущения!$B$25:$B$30,0),5))} -> 126700 | J10: =SUM(E10:I10) -> 298650 | L10: 70% трафика — мобильный 3G, картинки WebP
B11: Очереди / стриминг (Kafka, SQS) | C11: пользователи | D11: 0 | E11: {=IF($D11="","",$D11*INDEX(Допущения!$C$25:$G$30,MATCH($C11,Допущения!$B$25:$B$30,0),1))} -> 0 | F11: {=IF($D11="","",$D11*INDEX(Допущения!$C$25:$G$30,MATCH($C11,Допущения!$B$25:$B$30,0),2))} -> 0 | G11: {=IF($D11="","",$D11*INDEX(Допущения!$C$25:$G$30,MATCH($C11,Допущения!$B$25:$B$30,0),3))} -> 0 | H11: {=IF($D11="","",$D11*INDEX(Допущения!$C$25:$G$30,MATCH($C11,Допущения!$B$25:$B$30,0),4))} -> 0 | I11: {=IF($D11="","",$D11*INDEX(Допущения!$C$25:$G$30,MATCH($C11,Допущения!$B$25:$B$30,0),5))} -> 0 | J11: =SUM(E11:I11) -> 0 | L11: Асинхронные заказы и уведомления
B12: Резервный регион / DR | C12: пользователи | D12: 0 | E12: {=IF($D12="","",$D12*INDEX(Допущения!$C$25:$G$30,MATCH($C12,Допущения!$B$25:$B$30,0),1))} -> 0 | F12: {=IF($D12="","",$D12*INDEX(Допущения!$C$25:$G$30,MATCH($C12,Допущения!$B$25:$B$30,0),2))} -> 0 | G12: {=IF($D12="","",$D12*INDEX(Допущения!$C$25:$G$30,MATCH($C12,Допущения!$B$25:$B$30,0),3))} -> 0 | H12: {=IF($D12="","",$D12*INDEX(Допущения!$C$25:$G$30,MATCH($C12,Допущения!$B$25:$B$30,0),4))} -> 0 | I12: {=IF($D12="","",$D12*INDEX(Допущения!$C$25:$G$30,MATCH($C12,Допущения!$B$25:$B$30,0),5))} -> 0 | J12: =SUM(E12:I12) -> 0 | L12: Зависит от выбранной стратегии RTO/RPO
B13: Локальное размещение данных (NDPR, Нигерия) | C13: инфляция | D13: 11152.83 | E13: {=IF($D13="","",$D13*INDEX(Допущения!$C$25:$G$30,MATCH($C13,Допущения!$B$25:$B$30,0),1))} -> 11152.83 | F13: {=IF($D13="","",$D13*INDEX(Допущения!$C$25:$G$30,MATCH($C13,Допущения!$B$25:$B$30,0),2))} -> 12045.056 | G13: {=IF($D13="","",$D13*INDEX(Допущения!$C$25:$G$30,MATCH($C13,Допущения!$B$25:$B$30,0),3))} -> 13008.661 | H13: {=IF($D13="","",$D13*INDEX(Допущения!$C$25:$G$30,MATCH($C13,Допущения!$B$25:$B$30,0),4))} -> 14049.354 | I13: {=IF($D13="","",$D13*INDEX(Допущения!$C$25:$G$30,MATCH($C13,Допущения!$B$25:$B$30,0),5))} -> 15173.302 | J13: =SUM(E13:I13) -> 65429.203 | L13: Локальный провайдер или партнёр — см. ADR №3
C14: фикс | D14: 0 | E14: {=IF($D14="","",$D14*INDEX(Допущения!$C$25:$G$30,MATCH($C14,Допущения!$B$25:$B$30,0),1))} -> 0 | F14: {=IF($D14="","",$D14*INDEX(Допущения!$C$25:$G$30,MATCH($C14,Допущения!$B$25:$B$30,0),2))} -> 0 | G14: {=IF($D14="","",$D14*INDEX(Допущения!$C$25:$G$30,MATCH($C14,Допущения!$B$25:$B$30,0),3))} -> 0 | H14: {=IF($D14="","",$D14*INDEX(Допущения!$C$25:$G$30,MATCH($C14,Допущения!$B$25:$B$30,0),4))} -> 0 | I14: {=IF($D14="","",$D14*INDEX(Допущения!$C$25:$G$30,MATCH($C14,Допущения!$B$25:$B$30,0),5))} -> 0 | J14: =SUM(E14:I14) -> 0 | L14: Своя статья
B15: Итого по блоку | E15: =SUM(E7:E14) -> 64695.99 | F15: =SUM(F7:F14) -> 226217.7 | G15: =SUM(G7:G14) -> 548440.26 | H15: =SUM(H7:H14) -> 906435.35 | I15: =SUM(I7:I14) -> 1264513.7 | J15: =SUM(J7:J14) -> 3010303 | K15: =IFERROR(J15/$J$51,0) -> 0.079834207
B17: БЛОК 2. Лицензии, SaaS и инструменты
B18: Observability (метрики, логи, трейсинг) | C18: пользователи | D18: 1200 | E18: {=IF($D18="","",$D18*INDEX(Допущения!$C$25:$G$30,MATCH($C18,Допущения!$B$25:$B$30,0),1))} -> 1200 | F18: {=IF($D18="","",$D18*INDEX(Допущения!$C$25:$G$30,MATCH($C18,Допущения!$B$25:$B$30,0),2))} -> 4800 | G18: {=IF($D18="","",$D18*INDEX(Допущения!$C$25:$G$30,MATCH($C18,Допущения!$B$25:$B$30,0),3))} -> 12000 | H18: {=IF($D18="","",$D18*INDEX(Допущения!$C$25:$G$30,MATCH($C18,Допущения!$B$25:$B$30,0),4))} -> 20000 | I18: {=IF($D18="","",$D18*INDEX(Допущения!$C$25:$G$30,MATCH($C18,Допущения!$B$25:$B$30,0),5))} -> 28000 | J18: =SUM(E18:I18) -> 66000 | L18: Объём логов растёт с нагрузкой
B19: CI/CD, репозиторий, артефакты | C19: инфляция | D19: 600 | E19: {=IF($D19="","",$D19*INDEX(Допущения!$C$25:$G$30,MATCH($C19,Допущения!$B$25:$B$30,0),1))} -> 600 | F19: {=IF($D19="","",$D19*INDEX(Допущения!$C$25:$G$30,MATCH($C19,Допущения!$B$25:$B$30,0),2))} -> 648 | G19: {=IF($D19="","",$D19*INDEX(Допущения!$C$25:$G$30,MATCH($C19,Допущения!$B$25:$B$30,0),3))} -> 699.84 | H19: {=IF($D19="","",$D19*INDEX(Допущения!$C$25:$G$30,MATCH($C19,Допущения!$B$25:$B$30,0),4))} -> 755.8272 | I19: {=IF($D19="","",$D19*INDEX(Допущения!$C$25:$G$30,MATCH($C19,Допущения!$B$25:$B$30,0),5))} -> 816.29338 | J19: =SUM(E19:I19) -> 3519.9606 | L19: GitHub / GitLab, тарифы на команду
B20: Безопасность: WAF, секреты, антифрод | C20: пользователи | D20: 0 | E20: {=IF($D20="","",$D20*INDEX(Допущения!$C$25:$G$30,MATCH($C20,Допущения!$B$25:$B$30,0),1))} -> 0 | F20: {=IF($D20="","",$D20*INDEX(Допущения!$C$25:$G$30,MATCH($C20,Допущения!$B$25:$B$30,0),2))} -> 0 | G20: {=IF($D20="","",$D20*INDEX(Допущения!$C$25:$G$30,MATCH($C20,Допущения!$B$25:$B$30,0),3))} -> 0 | H20: {=IF($D20="","",$D20*INDEX(Допущения!$C$25:$G$30,MATCH($C20,Допущения!$B$25:$B$30,0),4))} -> 0 | I20: {=IF($D20="","",$D20*INDEX(Допущения!$C$25:$G$30,MATCH($C20,Допущения!$B$25:$B$30,0),5))} -> 0 | J20: =SUM(E20:I20) -> 0 | L20: Мошенничество на ПВЗ — риск из кейса
B21: WhatsApp Business API (подписка) | C21: инфляция | D21: 600 | E21: {=IF($D21="","",$D21*INDEX(Допущения!$C$25:$G$30,MATCH($C21,Допущения!$B$25:$B$30,0),1))} -> 600 | F21: {=IF($D21="","",$D21*INDEX(Допущения!$C$25:$G$30,MATCH($C21,Допущения!$B$25:$B$30,0),2))} -> 648 | G21: {=IF($D21="","",$D21*INDEX(Допущения!$C$25:$G$30,MATCH($C21,Допущения!$B$25:$B$30,0),3))} -> 699.84 | H21: {=IF($D21="","",$D21*INDEX(Допущения!$C$25:$G$30,MATCH($C21,Допущения!$B$25:$B$30,0),4))} -> 755.8272 | I21: {=IF($D21="","",$D21*INDEX(Допущения!$C$25:$G$30,MATCH($C21,Допущения!$B$25:$B$30,0),5))} -> 816.29338 | J21: =SUM(E21:I21) -> 3519.9606 | L21: Канал для продавцов без личного кабинета
B22: Прочее ПО и подписки | C22: инфляция | D22: 0 | E22: {=IF($D22="","",$D22*INDEX(Допущения!$C$25:$G$30,MATCH($C22,Допущения!$B$25:$B$30,0),1))} -> 0 | F22: {=IF($D22="","",$D22*INDEX(Допущения!$C$25:$G$30,MATCH($C22,Допущения!$B$25:$B$30,0),2))} -> 0 | G22: {=IF($D22="","",$D22*INDEX(Допущения!$C$25:$G$30,MATCH($C22,Допущения!$B$25:$B$30,0),3))} -> 0 | H22: {=IF($D22="","",$D22*INDEX(Допущения!$C$25:$G$30,MATCH($C22,Допущения!$B$25:$B$30,0),4))} -> 0 | I22: {=IF($D22="","",$D22*INDEX(Допущения!$C$25:$G$30,MATCH($C22,Допущения!$B$25:$B$30,0),5))} -> 0 | J22: =SUM(E22:I22) -> 0 | L22: Таск-трекер, дизайн, аналитика
C23: фикс | D23: 0 | E23: {=IF($D23="","",$D23*INDEX(Допущения!$C$25:$G$30,MATCH($C23,Допущения!$B$25:$B$30,0),1))} -> 0 | F23: {=IF($D23="","",$D23*INDEX(Допущения!$C$25:$G$30,MATCH($C23,Допущения!$B$25:$B$30,0),2))} -> 0 | G23: {=IF($D23="","",$D23*INDEX(Допущения!$C$25:$G$30,MATCH($C23,Допущения!$B$25:$B$30,0),3))} -> 0 | H23: {=IF($D23="","",$D23*INDEX(Допущения!$C$25:$G$30,MATCH($C23,Допущения!$B$25:$B$30,0),4))} -> 0 | I23: {=IF($D23="","",$D23*INDEX(Допущения!$C$25:$G$30,MATCH($C23,Допущения!$B$25:$B$30,0),5))} -> 0 | J23: =SUM(E23:I23) -> 0 | L23: Своя статья
B24: Итого по блоку | E24: =SUM(E18:E23) -> 2400 | F24: =SUM(F18:F23) -> 6096 | G24: =SUM(G18:G23) -> 13399.68 | H24: =SUM(H18:H23) -> 21511.654 | I24: =SUM(I18:I23) -> 29632.587 | J24: =SUM(J18:J23) -> 73039.921 | K24: =IFERROR(J24/$J$51,0) -> 0.0019370423
B26: БЛОК 3. Транзакционные расходы (Buy / Partner)
B27: Комиссии платёжных провайдеров | C27: GMV | D27: 137500 | E27: {=IF($D27="","",$D27*INDEX(Допущения!$C$25:$G$30,MATCH($C27,Допущения!$B$25:$B$30,0),1))} -> 137500 | F27: {=IF($D27="","",$D27*INDEX(Допущения!$C$25:$G$30,MATCH($C27,Допущения!$B$25:$B$30,0),2))} -> 858000 | G27: {=IF($D27="","",$D27*INDEX(Допущения!$C$25:$G$30,MATCH($C27,Допущения!$B$25:$B$30,0),3))} -> 2970000 | H27: {=IF($D27="","",$D27*INDEX(Допущения!$C$25:$G$30,MATCH($C27,Допущения!$B$25:$B$30,0),4))} -> 6160000 | I27: {=IF($D27="","",$D27*INDEX(Допущения!$C$25:$G$30,MATCH($C27,Допущения!$B$25:$B$30,0),5))} -> 9570000 | J27: =SUM(E27:I27) -> 19695500 | L27: ≈3% от GMV: M-Pesa (Кения), Flutterwave / Paystack (Нигерия)
B28: SMS-уведомления | C28: заказы | D28: 18000 | E28: {=IF($D28="","",$D28*INDEX(Допущения!$C$25:$G$30,MATCH($C28,Допущения!$B$25:$B$30,0),1))} -> 18000 | F28: {=IF($D28="","",$D28*INDEX(Допущения!$C$25:$G$30,MATCH($C28,Допущения!$B$25:$B$30,0),2))} -> 108000 | G28: {=IF($D28="","",$D28*INDEX(Допущения!$C$25:$G$30,MATCH($C28,Допущения!$B$25:$B$30,0),3))} -> 360000 | H28: {=IF($D28="","",$D28*INDEX(Допущения!$C$25:$G$30,MATCH($C28,Допущения!$B$25:$B$30,0),4))} -> 720000 | I28: {=IF($D28="","",$D28*INDEX(Допущения!$C$25:$G$30,MATCH($C28,Допущения!$B$25:$B$30,0),5))} -> 1080000 | J28: =SUM(E28:I28) -> 2286000 | L28: ≈$0,04 за SMS × заказы
B29: WhatsApp-сообщения (за диалог) | C29: заказы | D29: 7200 | E29: {=IF($D29="","",$D29*INDEX(Допущения!$C$25:$G$30,MATCH($C29,Допущения!$B$25:$B$30,0),1))} -> 7200 | F29: {=IF($D29="","",$D29*INDEX(Допущения!$C$25:$G$30,MATCH($C29,Допущения!$B$25:$B$30,0),2))} -> 43200 | G29: {=IF($D29="","",$D29*INDEX(Допущения!$C$25:$G$30,MATCH($C29,Допущения!$B$25:$B$30,0),3))} -> 144000 | H29: {=IF($D29="","",$D29*INDEX(Допущения!$C$25:$G$30,MATCH($C29,Допущения!$B$25:$B$30,0),4))} -> 288000 | I29: {=IF($D29="","",$D29*INDEX(Допущения!$C$25:$G$30,MATCH($C29,Допущения!$B$25:$B$30,0),5))} -> 432000 | J29: =SUM(E29:I29) -> 914400 | L29: Тариф Meta за conversation
B30: Логистика: интеграции и комиссии партнёров | C30: заказы | D30: =Допущения!C8*0.1 -> 30000 | E30: {=IF($D30="","",$D30*INDEX(Допущения!$C$25:$G$30,MATCH($C30,Допущения!$B$25:$B$30,0),1))} -> 30000 | F30: {=IF($D30="","",$D30*INDEX(Допущения!$C$25:$G$30,MATCH($C30,Допущения!$B$25:$B$30,0),2))} -> 180000 | G30: {=IF($D30="","",$D30*INDEX(Допущения!$C$25:$G$30,MATCH($C30,Допущения!$B$25:$B$30,0),3))} -> 600000 | H30: {=IF($D30="","",$D30*INDEX(Допущения!$C$25:$G$30,MATCH($C30,Допущения!$B$25:$B$30,0),4))} -> 1200000 | I30: {=IF($D30="","",$D30*INDEX(Допущения!$C$25:$G$30,MATCH($C30,Допущения!$B$25:$B$30,0),5))} -> 1800000 | J30: =SUM(E30:I30) -> 3810000 | L30: Sendbox (Нигерия), Sendy (Кения)
C31: фикс | D31: 0 | E31: {=IF($D31="","",$D31*INDEX(Допущения!$C$25:$G$30,MATCH($C31,Допущения!$B$25:$B$30,0),1))} -> 0 | F31: {=IF($D31="","",$D31*INDEX(Допущения!$C$25:$G$30,MATCH($C31,Допущения!$B$25:$B$30,0),2))} -> 0 | G31: {=IF($D31="","",$D31*INDEX(Допущения!$C$25:$G$30,MATCH($C31,Допущения!$B$25:$B$30,0),3))} -> 0 | H31: {=IF($D31="","",$D31*INDEX(Допущения!$C$25:$G$30,MATCH($C31,Допущения!$B$25:$B$30,0),4))} -> 0 | I31: {=IF($D31="","",$D31*INDEX(Допущения!$C$25:$G$30,MATCH($C31,Допущения!$B$25:$B$30,0),5))} -> 0 | J31: =SUM(E31:I31) -> 0 | L31: Своя статья
B32: Итого по блоку | E32: =SUM(E27:E31) -> 192700 | F32: =SUM(F27:F31) -> 1189200 | G32: =SUM(G27:G31) -> 4074000 | H32: =SUM(H27:H31) -> 8368000 | I32: =SUM(I27:I31) -> 12882000 | J32: =SUM(J27:J31) -> 26705900 | K32: =IFERROR(J32/$J$51,0) -> 0.70824908
B34: БЛОК 4. Команда (ФОТ)
B35: Разработка (FTE × годовая ставка) | C35: ФОТ | D35: 300000 | E35: {=IF($D35="","",$D35*INDEX(Допущения!$C$25:$G$30,MATCH($C35,Допущения!$B$25:$B$30,0),1))} -> 300000 | F35: {=IF($D35="","",$D35*INDEX(Допущения!$C$25:$G$30,MATCH($C35,Допущения!$B$25:$B$30,0),2))} -> 336000 | G35: {=IF($D35="","",$D35*INDEX(Допущения!$C$25:$G$30,MATCH($C35,Допущения!$B$25:$B$30,0),3))} -> 376320 | H35: {=IF($D35="","",$D35*INDEX(Допущения!$C$25:$G$30,MATCH($C35,Допущения!$B$25:$B$30,0),4))} -> 421478.4 | I35: {=IF($D35="","",$D35*INDEX(Допущения!$C$25:$G$30,MATCH($C35,Допущения!$B$25:$B$30,0),5))} -> 472055.81 | J35: =SUM(E35:I35) -> 1905854.2 | L35: Например 6 FTE × $60k. Зависит от арх. варианта!
B36: DevOps / SRE | C36: ФОТ | D36: 60000 | E36: {=IF($D36="","",$D36*INDEX(Допущения!$C$25:$G$30,MATCH($C36,Допущения!$B$25:$B$30,0),1))} -> 60000 | F36: {=IF($D36="","",$D36*INDEX(Допущения!$C$25:$G$30,MATCH($C36,Допущения!$B$25:$B$30,0),2))} -> 67200 | G36: {=IF($D36="","",$D36*INDEX(Допущения!$C$25:$G$30,MATCH($C36,Допущения!$B$25:$B$30,0),3))} -> 75264 | H36: {=IF($D36="","",$D36*INDEX(Допущения!$C$25:$G$30,MATCH($C36,Допущения!$B$25:$B$30,0),4))} -> 84295.68 | I36: {=IF($D36="","",$D36*INDEX(Допущения!$C$25:$G$30,MATCH($C36,Допущения!$B$25:$B$30,0),5))} -> 94411.162 | J36: =SUM(E36:I36) -> 381170.84 | L36: Микросервисы требуют больше SRE, чем монолит
B37: Поддержка и дежурства 24/7 | C37: ФОТ | D37: 12000 | E37: {=IF($D37="","",$D37*INDEX(Допущения!$C$25:$G$30,MATCH($C37,Допущения!$B$25:$B$30,0),1))} -> 12000 | F37: {=IF($D37="","",$D37*INDEX(Допущения!$C$25:$G$30,MATCH($C37,Допущения!$B$25:$B$30,0),2))} -> 13440 | G37: {=IF($D37="","",$D37*INDEX(Допущения!$C$25:$G$30,MATCH($C37,Допущения!$B$25:$B$30,0),3))} -> 15052.8 | H37: {=IF($D37="","",$D37*INDEX(Допущения!$C$25:$G$30,MATCH($C37,Допущения!$B$25:$B$30,0),4))} -> 16859.136 | I37: {=IF($D37="","",$D37*INDEX(Допущения!$C$25:$G$30,MATCH($C37,Допущения!$B$25:$B$30,0),5))} -> 18882.232 | J37: =SUM(E37:I37) -> 76234.168 | L37: Требование mission critical: дежурство ночью
B38: Архитектура и менеджмент | C38: ФОТ | D38: 24000 | E38: {=IF($D38="","",$D38*INDEX(Допущения!$C$25:$G$30,MATCH($C38,Допущения!$B$25:$B$30,0),1))} -> 24000 | F38: {=IF($D38="","",$D38*INDEX(Допущения!$C$25:$G$30,MATCH($C38,Допущения!$B$25:$B$30,0),2))} -> 26880 | G38: {=IF($D38="","",$D38*INDEX(Допущения!$C$25:$G$30,MATCH($C38,Допущения!$B$25:$B$30,0),3))} -> 30105.6 | H38: {=IF($D38="","",$D38*INDEX(Допущения!$C$25:$G$30,MATCH($C38,Допущения!$B$25:$B$30,0),4))} -> 33718.272 | I38: {=IF($D38="","",$D38*INDEX(Допущения!$C$25:$G$30,MATCH($C38,Допущения!$B$25:$B$30,0),5))} -> 37764.465 | J38: =SUM(E38:I38) -> 152468.34 | L38: Solution Architect, CTO-функция, PM
C39: фикс | D39: 0 | E39: {=IF($D39="","",$D39*INDEX(Допущения!$C$25:$G$30,MATCH($C39,Допущения!$B$25:$B$30,0),1))} -> 0 | F39: {=IF($D39="","",$D39*INDEX(Допущения!$C$25:$G$30,MATCH($C39,Допущения!$B$25:$B$30,0),2))} -> 0 | G39: {=IF($D39="","",$D39*INDEX(Допущения!$C$25:$G$30,MATCH($C39,Допущения!$B$25:$B$30,0),3))} -> 0 | H39: {=IF($D39="","",$D39*INDEX(Допущения!$C$25:$G$30,MATCH($C39,Допущения!$B$25:$B$30,0),4))} -> 0 | I39: {=IF($D39="","",$D39*INDEX(Допущения!$C$25:$G$30,MATCH($C39,Допущения!$B$25:$B$30,0),5))} -> 0 | J39: =SUM(E39:I39) -> 0 | L39: Своя статья
B40: Итого по блоку | E40: =SUM(E35:E39) -> 396000 | F40: =SUM(F35:F39) -> 443520 | G40: =SUM(G35:G39) -> 496742.4 | H40: =SUM(H35:H39) -> 556351.49 | I40: =SUM(I35:I39) -> 623113.67 | J40: =SUM(J35:J39) -> 2515727.6 | K40: =IFERROR(J40/$J$51,0) -> 0.066717906
B42: БЛОК 5. Разовые затраты и комплаенс
B43: Юридический и комплаенс-аудит (NDPR, POPIA, KICA) | C43: фикс | D43: 15000 | E43: {=IF($D43="","",$D43*INDEX(Допущения!$C$25:$G$30,MATCH($C43,Допущения!$B$25:$B$30,0),1))} -> 15000 | F43: {=IF($D43="","",$D43*INDEX(Допущения!$C$25:$G$30,MATCH($C43,Допущения!$B$25:$B$30,0),2))} -> 15000 | G43: {=IF($D43="","",$D43*INDEX(Допущения!$C$25:$G$30,MATCH($C43,Допущения!$B$25:$B$30,0),3))} -> 15000 | H43: {=IF($D43="","",$D43*INDEX(Допущения!$C$25:$G$30,MATCH($C43,Допущения!$B$25:$B$30,0),4))} -> 15000 | I43: {=IF($D43="","",$D43*INDEX(Допущения!$C$25:$G$30,MATCH($C43,Допущения!$B$25:$B$30,0),5))} -> 15000 | J43: =SUM(E43:I43) -> 75000 | L43: Разовая статья — обнули лишние годы вручную
B44: Пентест и аудит безопасности | C44: инфляция | D44: 10000 | E44: {=IF($D44="","",$D44*INDEX(Допущения!$C$25:$G$30,MATCH($C44,Допущения!$B$25:$B$30,0),1))} -> 10000 | F44: {=IF($D44="","",$D44*INDEX(Допущения!$C$25:$G$30,MATCH($C44,Допущения!$B$25:$B$30,0),2))} -> 10800 | G44: {=IF($D44="","",$D44*INDEX(Допущения!$C$25:$G$30,MATCH($C44,Допущения!$B$25:$B$30,0),3))} -> 11664 | H44: {=IF($D44="","",$D44*INDEX(Допущения!$C$25:$G$30,MATCH($C44,Допущения!$B$25:$B$30,0),4))} -> 12597.12 | I44: {=IF($D44="","",$D44*INDEX(Допущения!$C$25:$G$30,MATCH($C44,Допущения!$B$25:$B$30,0),5))} -> 13604.89 | J44: =SUM(E44:I44) -> 58666.01 | L44: Ежегодно, если mission critical
B45: Миграция данных и интеграции при запуске | C45: фикс | D45: 70000 | E45: {=IF($D45="","",$D45*INDEX(Допущения!$C$25:$G$30,MATCH($C45,Допущения!$B$25:$B$30,0),1))} -> 70000 | F45: {=IF($D45="","",$D45*INDEX(Допущения!$C$25:$G$30,MATCH($C45,Допущения!$B$25:$B$30,0),2))} -> 70000 | G45: {=IF($D45="","",$D45*INDEX(Допущения!$C$25:$G$30,MATCH($C45,Допущения!$B$25:$B$30,0),3))} -> 70000 | H45: {=IF($D45="","",$D45*INDEX(Допущения!$C$25:$G$30,MATCH($C45,Допущения!$B$25:$B$30,0),4))} -> 70000 | I45: {=IF($D45="","",$D45*INDEX(Допущения!$C$25:$G$30,MATCH($C45,Допущения!$B$25:$B$30,0),5))} -> 70000 | J45: =SUM(E45:I45) -> 350000 | L45: Разовая статья
B46: Обучение команды и найм | C46: ФОТ | D46: 0 | E46: {=IF($D46="","",$D46*INDEX(Допущения!$C$25:$G$30,MATCH($C46,Допущения!$B$25:$B$30,0),1))} -> 0 | F46: {=IF($D46="","",$D46*INDEX(Допущения!$C$25:$G$30,MATCH($C46,Допущения!$B$25:$B$30,0),2))} -> 0 | G46: {=IF($D46="","",$D46*INDEX(Допущения!$C$25:$G$30,MATCH($C46,Допущения!$B$25:$B$30,0),3))} -> 0 | H46: {=IF($D46="","",$D46*INDEX(Допущения!$C$25:$G$30,MATCH($C46,Допущения!$B$25:$B$30,0),4))} -> 0 | I46: {=IF($D46="","",$D46*INDEX(Допущения!$C$25:$G$30,MATCH($C46,Допущения!$B$25:$B$30,0),5))} -> 0 | J46: =SUM(E46:I46) -> 0 | L46: Дефицит локальных ИТ-специалистов
...

Sheet TCO-B
B2: TCO на 5 лет — Africa Delivery
B3: Заполняем колонки «Драйвер роста» и «База, $/год (Год 1)». Годы 1–5 считаются автоматически.
B5: Статья затрат | C5: Драйвер роста | D5: База, $/год (Год 1) | E5: Год 1 | F5: Год 2 | G5: Год 3 | H5: Год 4 | I5: Год 5 | J5: Итого 5 лет | K5: Доля | L5: Комментарий / источник
B6: БЛОК 1. Облачная инфраструктура (OpEx)
B7: Compute: ноды / контейнеры / serverless | C7: пользователи | D7: 18525.26 | E7: {=IF($D7="","",$D7*INDEX(Допущения!$C$25:$G$30,MATCH($C7,Допущения!$B$25:$B$30,0),1))} -> 18525.26 | F7: {=IF($D7="","",$D7*INDEX(Допущения!$C$25:$G$30,MATCH($C7,Допущения!$B$25:$B$30,0),2))} -> 74101.04 | G7: {=IF($D7="","",$D7*INDEX(Допущения!$C$25:$G$30,MATCH($C7,Допущения!$B$25:$B$30,0),3))} -> 185252.6 | H7: {=IF($D7="","",$D7*INDEX(Допущения!$C$25:$G$30,MATCH($C7,Допущения!$B$25:$B$30,0),4))} -> 308754.33 | I7: {=IF($D7="","",$D7*INDEX(Допущения!$C$25:$G$30,MATCH($C7,Допущения!$B$25:$B$30,0),5))} -> 432256.07 | J7: =SUM(E7:I7) -> 1018889.3 | L7: AWS af-south-1, оценка по калькулятору
B8: Управляемые БД (PostgreSQL, реплики) | C8: пользователи | D8: 27787.9 | E8: {=IF($D8="","",$D8*INDEX(Допущения!$C$25:$G$30,MATCH($C8,Допущения!$B$25:$B$30,0),1))} -> 27787.9 | F8: {=IF($D8="","",$D8*INDEX(Допущения!$C$25:$G$30,MATCH($C8,Допущения!$B$25:$B$30,0),2))} -> 111151.6 | G8: {=IF($D8="","",$D8*INDEX(Допущения!$C$25:$G$30,MATCH($C8,Допущения!$B$25:$B$30,0),3))} -> 277879 | H8: {=IF($D8="","",$D8*INDEX(Допущения!$C$25:$G$30,MATCH($C8,Допущения!$B$25:$B$30,0),4))} -> 463131.67 | I8: {=IF($D8="","",$D8*INDEX(Допущения!$C$25:$G$30,MATCH($C8,Допущения!$B$25:$B$30,0),5))} -> 648384.33 | J8: =SUM(E8:I8) -> 1528334.5 | L8: Managed RDS + read replica
B9: Хранилище объектов и резервные копии | C9: пользователи | D9: 1800 | E9: {=IF($D9="","",$D9*INDEX(Допущения!$C$25:$G$30,MATCH($C9,Допущения!$B$25:$B$30,0),1))} -> 1800 | F9: {=IF($D9="","",$D9*INDEX(Допущения!$C$25:$G$30,MATCH($C9,Допущения!$B$25:$B$30,0),2))} -> 7200 | G9: {=IF($D9="","",$D9*INDEX(Допущения!$C$25:$G$30,MATCH($C9,Допущения!$B$25:$B$30,0),3))} -> 18000 | H9: {=IF($D9="","",$D9*INDEX(Допущения!$C$25:$G$30,MATCH($C9,Допущения!$B$25:$B$30,0),4))} -> 30000 | I9: {=IF($D9="","",$D9*INDEX(Допущения!$C$25:$G$30,MATCH($C9,Допущения!$B$25:$B$30,0),5))} -> 42000 | J9: =SUM(E9:I9) -> 99000 | L9: Фото товаров, 5000 SKU на старте
B10: CDN и исходящий трафик | C10: пользователи | D10: 6030 | E10: {=IF($D10="","",$D10*INDEX(Допущения!$C$25:$G$30,MATCH($C10,Допущения!$B$25:$B$30,0),1))} -> 6030 | F10: {=IF($D10="","",$D10*INDEX(Допущения!$C$25:$G$30,MATCH($C10,Допущения!$B$25:$B$30,0),2))} -> 24120 | G10: {=IF($D10="","",$D10*INDEX(Допущения!$C$25:$G$30,MATCH($C10,Допущения!$B$25:$B$30,0),3))} -> 60300 | H10: {=IF($D10="","",$D10*INDEX(Допущения!$C$25:$G$30,MATCH($C10,Допущения!$B$25:$B$30,0),4))} -> 100500 | I10: {=IF($D10="","",$D10*INDEX(Допущения!$C$25:$G$30,MATCH($C10,Допущения!$B$25:$B$30,0),5))} -> 140700 | J10: =SUM(E10:I10) -> 331650 | L10: 70% трафика — мобильный 3G, картинки WebP
B11: Очереди / стриминг (Kafka, SQS) | C11: пользователи | D11: 0 | E11: {=IF($D11="","",$D11*INDEX(Допущения!$C$25:$G$30,MATCH($C11,Допущения!$B$25:$B$30,0),1))} -> 0 | F11: {=IF($D11="","",$D11*INDEX(Допущения!$C$25:$G$30,MATCH($C11,Допущения!$B$25:$B$30,0),2))} -> 0 | G11: {=IF($D11="","",$D11*INDEX(Допущения!$C$25:$G$30,MATCH($C11,Допущения!$B$25:$B$30,0),3))} -> 0 | H11: {=IF($D11="","",$D11*INDEX(Допущения!$C$25:$G$30,MATCH($C11,Допущения!$B$25:$B$30,0),4))} -> 0 | I11: {=IF($D11="","",$D11*INDEX(Допущения!$C$25:$G$30,MATCH($C11,Допущения!$B$25:$B$30,0),5))} -> 0 | J11: =SUM(E11:I11) -> 0 | L11: Асинхронные заказы и уведомления
B12: Резервный регион / DR | C12: пользователи | D12: 11152.83 | E12: {=IF($D12="","",$D12*INDEX(Допущения!$C$25:$G$30,MATCH($C12,Допущения!$B$25:$B$30,0),1))} -> 11152.83 | F12: {=IF($D12="","",$D12*INDEX(Допущения!$C$25:$G$30,MATCH($C12,Допущения!$B$25:$B$30,0),2))} -> 44611.32 | G12: {=IF($D12="","",$D12*INDEX(Допущения!$C$25:$G$30,MATCH($C12,Допущения!$B$25:$B$30,0),3))} -> 111528.3 | H12: {=IF($D12="","",$D12*INDEX(Допущения!$C$25:$G$30,MATCH($C12,Допущения!$B$25:$B$30,0),4))} -> 185880.5 | I12: {=IF($D12="","",$D12*INDEX(Допущения!$C$25:$G$30,MATCH($C12,Допущения!$B$25:$B$30,0),5))} -> 260232.7 | J12: =SUM(E12:I12) -> 613405.65 | L12: Зависит от выбранной стратегии RTO/RPO
B13: Локальное размещение данных (NDPR, Нигерия) | C13: инфляция | D13: 0 | E13: {=IF($D13="","",$D13*INDEX(Допущения!$C$25:$G$30,MATCH($C13,Допущения!$B$25:$B$30,0),1))} -> 0 | F13: {=IF($D13="","",$D13*INDEX(Допущения!$C$25:$G$30,MATCH($C13,Допущения!$B$25:$B$30,0),2))} -> 0 | G13: {=IF($D13="","",$D13*INDEX(Допущения!$C$25:$G$30,MATCH($C13,Допущения!$B$25:$B$30,0),3))} -> 0 | H13: {=IF($D13="","",$D13*INDEX(Допущения!$C$25:$G$30,MATCH($C13,Допущения!$B$25:$B$30,0),4))} -> 0 | I13: {=IF($D13="","",$D13*INDEX(Допущения!$C$25:$G$30,MATCH($C13,Допущения!$B$25:$B$30,0),5))} -> 0 | J13: =SUM(E13:I13) -> 0 | L13: Локальный провайдер или партнёр — см. ADR №3
C14: фикс | D14: 0 | E14: {=IF($D14="","",$D14*INDEX(Допущения!$C$25:$G$30,MATCH($C14,Допущения!$B$25:$B$30,0),1))} -> 0 | F14: {=IF($D14="","",$D14*INDEX(Допущения!$C$25:$G$30,MATCH($C14,Допущения!$B$25:$B$30,0),2))} -> 0 | G14: {=IF($D14="","",$D14*INDEX(Допущения!$C$25:$G$30,MATCH($C14,Допущения!$B$25:$B$30,0),3))} -> 0 | H14: {=IF($D14="","",$D14*INDEX(Допущения!$C$25:$G$30,MATCH($C14,Допущения!$B$25:$B$30,0),4))} -> 0 | I14: {=IF($D14="","",$D14*INDEX(Допущения!$C$25:$G$30,MATCH($C14,Допущения!$B$25:$B$30,0),5))} -> 0 | J14: =SUM(E14:I14) -> 0 | L14: Своя статья
B15: Итого по блоку | E15: =SUM(E7:E14) -> 65295.99 | F15: =SUM(F7:F14) -> 261183.96 | G15: =SUM(G7:G14) -> 652959.9 | H15: =SUM(H7:H14) -> 1088266.5 | I15: =SUM(I7:I14) -> 1523573.1 | J15: =SUM(J7:J14) -> 3591279.4 | K15: =IFERROR(J15/$J$51,0) -> 0.09102275
B17: БЛОК 2. Лицензии, SaaS и инструменты
B18: Observability (метрики, логи, трейсинг) | C18: пользователи | D18: 1800 | E18: {=IF($D18="","",$D18*INDEX(Допущения!$C$25:$G$30,MATCH($C18,Допущения!$B$25:$B$30,0),1))} -> 1800 | F18: {=IF($D18="","",$D18*INDEX(Допущения!$C$25:$G$30,MATCH($C18,Допущения!$B$25:$B$30,0),2))} -> 7200 | G18: {=IF($D18="","",$D18*INDEX(Допущения!$C$25:$G$30,MATCH($C18,Допущения!$B$25:$B$30,0),3))} -> 18000 | H18: {=IF($D18="","",$D18*INDEX(Допущения!$C$25:$G$30,MATCH($C18,Допущения!$B$25:$B$30,0),4))} -> 30000 | I18: {=IF($D18="","",$D18*INDEX(Допущения!$C$25:$G$30,MATCH($C18,Допущения!$B$25:$B$30,0),5))} -> 42000 | J18: =SUM(E18:I18) -> 99000 | L18: Объём логов растёт с нагрузкой
B19: CI/CD, репозиторий, артефакты | C19: инфляция | D19: 1200 | E19: {=IF($D19="","",$D19*INDEX(Допущения!$C$25:$G$30,MATCH($C19,Допущения!$B$25:$B$30,0),1))} -> 1200 | F19: {=IF($D19="","",$D19*INDEX(Допущения!$C$25:$G$30,MATCH($C19,Допущения!$B$25:$B$30,0),2))} -> 1296 | G19: {=IF($D19="","",$D19*INDEX(Допущения!$C$25:$G$30,MATCH($C19,Допущения!$B$25:$B$30,0),3))} -> 1399.68 | H19: {=IF($D19="","",$D19*INDEX(Допущения!$C$25:$G$30,MATCH($C19,Допущения!$B$25:$B$30,0),4))} -> 1511.6544 | I19: {=IF($D19="","",$D19*INDEX(Допущения!$C$25:$G$30,MATCH($C19,Допущения!$B$25:$B$30,0),5))} -> 1632.5868 | J19: =SUM(E19:I19) -> 7039.9212 | L19: GitHub / GitLab, тарифы на команду
B20: Безопасность: WAF, секреты, антифрод | C20: пользователи | D20: 0 | E20: {=IF($D20="","",$D20*INDEX(Допущения!$C$25:$G$30,MATCH($C20,Допущения!$B$25:$B$30,0),1))} -> 0 | F20: {=IF($D20="","",$D20*INDEX(Допущения!$C$25:$G$30,MATCH($C20,Допущения!$B$25:$B$30,0),2))} -> 0 | G20: {=IF($D20="","",$D20*INDEX(Допущения!$C$25:$G$30,MATCH($C20,Допущения!$B$25:$B$30,0),3))} -> 0 | H20: {=IF($D20="","",$D20*INDEX(Допущения!$C$25:$G$30,MATCH($C20,Допущения!$B$25:$B$30,0),4))} -> 0 | I20: {=IF($D20="","",$D20*INDEX(Допущения!$C$25:$G$30,MATCH($C20,Допущения!$B$25:$B$30,0),5))} -> 0 | J20: =SUM(E20:I20) -> 0 | L20: Мошенничество на ПВЗ — риск из кейса
B21: WhatsApp Business API (подписка) | C21: инфляция | D21: 600 | E21: {=IF($D21="","",$D21*INDEX(Допущения!$C$25:$G$30,MATCH($C21,Допущения!$B$25:$B$30,0),1))} -> 600 | F21: {=IF($D21="","",$D21*INDEX(Допущения!$C$25:$G$30,MATCH($C21,Допущения!$B$25:$B$30,0),2))} -> 648 | G21: {=IF($D21="","",$D21*INDEX(Допущения!$C$25:$G$30,MATCH($C21,Допущения!$B$25:$B$30,0),3))} -> 699.84 | H21: {=IF($D21="","",$D21*INDEX(Допущения!$C$25:$G$30,MATCH($C21,Допущения!$B$25:$B$30,0),4))} -> 755.8272 | I21: {=IF($D21="","",$D21*INDEX(Допущения!$C$25:$G$30,MATCH($C21,Допущения!$B$25:$B$30,0),5))} -> 816.29338 | J21: =SUM(E21:I21) -> 3519.9606 | L21: Канал для продавцов без личного кабинета
B22: Прочее ПО и подписки | C22: инфляция | D22: 0 | E22: {=IF($D22="","",$D22*INDEX(Допущения!$C$25:$G$30,MATCH($C22,Допущения!$B$25:$B$30,0),1))} -> 0 | F22: {=IF($D22="","",$D22*INDEX(Допущения!$C$25:$G$30,MATCH($C22,Допущения!$B$25:$B$30,0),2))} -> 0 | G22: {=IF($D22="","",$D22*INDEX(Допущения!$C$25:$G$30,MATCH($C22,Допущения!$B$25:$B$30,0),3))} -> 0 | H22: {=IF($D22="","",$D22*INDEX(Допущения!$C$25:$G$30,MATCH($C22,Допущения!$B$25:$B$30,0),4))} -> 0 | I22: {=IF($D22="","",$D22*INDEX(Допущения!$C$25:$G$30,MATCH($C22,Допущения!$B$25:$B$30,0),5))} -> 0 | J22: =SUM(E22:I22) -> 0 | L22: Таск-трекер, дизайн, аналитика
C23: фикс | D23: 0 | E23: {=IF($D23="","",$D23*INDEX(Допущения!$C$25:$G$30,MATCH($C23,Допущения!$B$25:$B$30,0),1))} -> 0 | F23: {=IF($D23="","",$D23*INDEX(Допущения!$C$25:$G$30,MATCH($C23,Допущения!$B$25:$B$30,0),2))} -> 0 | G23: {=IF($D23="","",$D23*INDEX(Допущения!$C$25:$G$30,MATCH($C23,Допущения!$B$25:$B$30,0),3))} -> 0 | H23: {=IF($D23="","",$D23*INDEX(Допущения!$C$25:$G$30,MATCH($C23,Допущения!$B$25:$B$30,0),4))} -> 0 | I23: {=IF($D23="","",$D23*INDEX(Допущения!$C$25:$G$30,MATCH($C23,Допущения!$B$25:$B$30,0),5))} -> 0 | J23: =SUM(E23:I23) -> 0 | L23: Своя статья
B24: Итого по блоку | E24: =SUM(E18:E23) -> 3600 | F24: =SUM(F18:F23) -> 9144 | G24: =SUM(G18:G23) -> 20099.52 | H24: =SUM(H18:H23) -> 32267.482 | I24: =SUM(I18:I23) -> 44448.88 | J24: =SUM(J18:J23) -> 109559.88 | K24: =IFERROR(J24/$J$51,0) -> 0.0027768493
B26: БЛОК 3. Транзакционные расходы (Buy / Partner)
B27: Комиссии платёжных провайдеров | C27: GMV | D27: 137500 | E27: {=IF($D27="","",$D27*INDEX(Допущения!$C$25:$G$30,MATCH($C27,Допущения!$B$25:$B$30,0),1))} -> 137500 | F27: {=IF($D27="","",$D27*INDEX(Допущения!$C$25:$G$30,MATCH($C27,Допущения!$B$25:$B$30,0),2))} -> 858000 | G27: {=IF($D27="","",$D27*INDEX(Допущения!$C$25:$G$30,MATCH($C27,Допущения!$B$25:$B$30,0),3))} -> 2970000 | H27: {=IF($D27="","",$D27*INDEX(Допущения!$C$25:$G$30,MATCH($C27,Допущения!$B$25:$B$30,0),4))} -> 6160000 | I27: {=IF($D27="","",$D27*INDEX(Допущения!$C$25:$G$30,MATCH($C27,Допущения!$B$25:$B$30,0),5))} -> 9570000 | J27: =SUM(E27:I27) -> 19695500 | L27: ≈3% от GMV: M-Pesa (Кения), Flutterwave / Paystack (Нигерия)
B28: SMS-уведомления | C28: заказы | D28: 18000 | E28: {=IF($D28="","",$D28*INDEX(Допущения!$C$25:$G$30,MATCH($C28,Допущения!$B$25:$B$30,0),1))} -> 18000 | F28: {=IF($D28="","",$D28*INDEX(Допущения!$C$25:$G$30,MATCH($C28,Допущения!$B$25:$B$30,0),2))} -> 108000 | G28: {=IF($D28="","",$D28*INDEX(Допущения!$C$25:$G$30,MATCH($C28,Допущения!$B$25:$B$30,0),3))} -> 360000 | H28: {=IF($D28="","",$D28*INDEX(Допущения!$C$25:$G$30,MATCH($C28,Допущения!$B$25:$B$30,0),4))} -> 720000 | I28: {=IF($D28="","",$D28*INDEX(Допущения!$C$25:$G$30,MATCH($C28,Допущения!$B$25:$B$30,0),5))} -> 1080000 | J28: =SUM(E28:I28) -> 2286000 | L28: ≈$0,04 за SMS × заказы
B29: WhatsApp-сообщения (за диалог) | C29: заказы | D29: 7200 | E29: {=IF($D29="","",$D29*INDEX(Допущения!$C$25:$G$30,MATCH($C29,Допущения!$B$25:$B$30,0),1))} -> 7200 | F29: {=IF($D29="","",$D29*INDEX(Допущения!$C$25:$G$30,MATCH($C29,Допущения!$B$25:$B$30,0),2))} -> 43200 | G29: {=IF($D29="","",$D29*INDEX(Допущения!$C$25:$G$30,MATCH($C29,Допущения!$B$25:$B$30,0),3))} -> 144000 | H29: {=IF($D29="","",$D29*INDEX(Допущения!$C$25:$G$30,MATCH($C29,Допущения!$B$25:$B$30,0),4))} -> 288000 | I29: {=IF($D29="","",$D29*INDEX(Допущения!$C$25:$G$30,MATCH($C29,Допущения!$B$25:$B$30,0),5))} -> 432000 | J29: =SUM(E29:I29) -> 914400 | L29: Тариф Meta за conversation
B30: Логистика: интеграции и комиссии партнёров | C30: заказы | D30: =Допущения!C8*0.1 -> 30000 | E30: {=IF($D30="","",$D30*INDEX(Допущения!$C$25:$G$30,MATCH($C30,Допущения!$B$25:$B$30,0),1))} -> 30000 | F30: {=IF($D30="","",$D30*INDEX(Допущения!$C$25:$G$30,MATCH($C30,Допущения!$B$25:$B$30,0),2))} -> 180000 | G30: {=IF($D30="","",$D30*INDEX(Допущения!$C$25:$G$30,MATCH($C30,Допущения!$B$25:$B$30,0),3))} -> 600000 | H30: {=IF($D30="","",$D30*INDEX(Допущения!$C$25:$G$30,MATCH($C30,Допущения!$B$25:$B$30,0),4))} -> 1200000 | I30: {=IF($D30="","",$D30*INDEX(Допущения!$C$25:$G$30,MATCH($C30,Допущения!$B$25:$B$30,0),5))} -> 1800000 | J30: =SUM(E30:I30) -> 3810000 | L30: Sendbox (Нигерия), Sendy (Кения)
C31: фикс | D31: 0 | E31: {=IF($D31="","",$D31*INDEX(Допущения!$C$25:$G$30,MATCH($C31,Допущения!$B$25:$B$30,0),1))} -> 0 | F31: {=IF($D31="","",$D31*INDEX(Допущения!$C$25:$G$30,MATCH($C31,Допущения!$B$25:$B$30,0),2))} -> 0 | G31: {=IF($D31="","",$D31*INDEX(Допущения!$C$25:$G$30,MATCH($C31,Допущения!$B$25:$B$30,0),3))} -> 0 | H31: {=IF($D31="","",$D31*INDEX(Допущения!$C$25:$G$30,MATCH($C31,Допущения!$B$25:$B$30,0),4))} -> 0 | I31: {=IF($D31="","",$D31*INDEX(Допущения!$C$25:$G$30,MATCH($C31,Допущения!$B$25:$B$30,0),5))} -> 0 | J31: =SUM(E31:I31) -> 0 | L31: Своя статья
B32: Итого по блоку | E32: =SUM(E27:E31) -> 192700 | F32: =SUM(F27:F31) -> 1189200 | G32: =SUM(G27:G31) -> 4074000 | H32: =SUM(H27:H31) -> 8368000 | I32: =SUM(I27:I31) -> 12882000 | J32: =SUM(J27:J31) -> 26705900 | K32: =IFERROR(J32/$J$51,0) -> 0.67687421
B34: БЛОК 4. Команда (ФОТ)
B35: Разработка (FTE × годовая ставка) | C35: ФОТ | D35: 360000 | E35: {=IF($D35="","",$D35*INDEX(Допущения!$C$25:$G$30,MATCH($C35,Допущения!$B$25:$B$30,0),1))} -> 360000 | F35: {=IF($D35="","",$D35*INDEX(Допущения!$C$25:$G$30,MATCH($C35,Допущения!$B$25:$B$30,0),2))} -> 403200 | G35: {=IF($D35="","",$D35*INDEX(Допущения!$C$25:$G$30,MATCH($C35,Допущения!$B$25:$B$30,0),3))} -> 451584 | H35: {=IF($D35="","",$D35*INDEX(Допущения!$C$25:$G$30,MATCH($C35,Допущения!$B$25:$B$30,0),4))} -> 505774.08 | I35: {=IF($D35="","",$D35*INDEX(Допущения!$C$25:$G$30,MATCH($C35,Допущения!$B$25:$B$30,0),5))} -> 566466.97 | J35: =SUM(E35:I35) -> 2287025 | L35: Например 6 FTE × $60k. Зависит от арх. варианта!
B36: DevOps / SRE | C36: ФОТ | D36: 120000 | E36: {=IF($D36="","",$D36*INDEX(Допущения!$C$25:$G$30,MATCH($C36,Допущения!$B$25:$B$30,0),1))} -> 120000 | F36: {=IF($D36="","",$D36*INDEX(Допущения!$C$25:$G$30,MATCH($C36,Допущения!$B$25:$B$30,0),2))} -> 134400 | G36: {=IF($D36="","",$D36*INDEX(Допущения!$C$25:$G$30,MATCH($C36,Допущения!$B$25:$B$30,0),3))} -> 150528 | H36: {=IF($D36="","",$D36*INDEX(Допущения!$C$25:$G$30,MATCH($C36,Допущения!$B$25:$B$30,0),4))} -> 168591.36 | I36: {=IF($D36="","",$D36*INDEX(Допущения!$C$25:$G$30,MATCH($C36,Допущения!$B$25:$B$30,0),5))} -> 188822.32 | J36: =SUM(E36:I36) -> 762341.68 | L36: Микросервисы требуют больше SRE, чем монолит
B37: Поддержка и дежурства 24/7 | C37: ФОТ | D37: 12000 | E37: {=IF($D37="","",$D37*INDEX(Допущения!$C$25:$G$30,MATCH($C37,Допущения!$B$25:$B$30,0),1))} -> 12000 | F37: {=IF($D37="","",$D37*INDEX(Допущения!$C$25:$G$30,MATCH($C37,Допущения!$B$25:$B$30,0),2))} -> 13440 | G37: {=IF($D37="","",$D37*INDEX(Допущения!$C$25:$G$30,MATCH($C37,Допущения!$B$25:$B$30,0),3))} -> 15052.8 | H37: {=IF($D37="","",$D37*INDEX(Допущения!$C$25:$G$30,MATCH($C37,Допущения!$B$25:$B$30,0),4))} -> 16859.136 | I37: {=IF($D37="","",$D37*INDEX(Допущения!$C$25:$G$30,MATCH($C37,Допущения!$B$25:$B$30,0),5))} -> 18882.232 | J37: =SUM(E37:I37) -> 76234.168 | L37: Требование mission critical: дежурство ночью
B38: Архитектура и менеджмент | C38: ФОТ | D38: 24000 | E38: {=IF($D38="","",$D38*INDEX(Допущения!$C$25:$G$30,MATCH($C38,Допущения!$B$25:$B$30,0),1))} -> 24000 | F38: {=IF($D38="","",$D38*INDEX(Допущения!$C$25:$G$30,MATCH($C38,Допущения!$B$25:$B$30,0),2))} -> 26880 | G38: {=IF($D38="","",$D38*INDEX(Допущения!$C$25:$G$30,MATCH($C38,Допущения!$B$25:$B$30,0),3))} -> 30105.6 | H38: {=IF($D38="","",$D38*INDEX(Допущения!$C$25:$G$30,MATCH($C38,Допущения!$B$25:$B$30,0),4))} -> 33718.272 | I38: {=IF($D38="","",$D38*INDEX(Допущения!$C$25:$G$30,MATCH($C38,Допущения!$B$25:$B$30,0),5))} -> 37764.465 | J38: =SUM(E38:I38) -> 152468.34 | L38: Solution Architect, CTO-функция, PM
C39: фикс | D39: 0 | E39: {=IF($D39="","",$D39*INDEX(Допущения!$C$25:$G$30,MATCH($C39,Допущения!$B$25:$B$30,0),1))} -> 0 | F39: {=IF($D39="","",$D39*INDEX(Допущения!$C$25:$G$30,MATCH($C39,Допущения!$B$25:$B$30,0),2))} -> 0 | G39: {=IF($D39="","",$D39*INDEX(Допущения!$C$25:$G$30,MATCH($C39,Допущения!$B$25:$B$30,0),3))} -> 0 | H39: {=IF($D39="","",$D39*INDEX(Допущения!$C$25:$G$30,MATCH($C39,Допущения!$B$25:$B$30,0),4))} -> 0 | I39: {=IF($D39="","",$D39*INDEX(Допущения!$C$25:$G$30,MATCH($C39,Допущения!$B$25:$B$30,0),5))} -> 0 | J39: =SUM(E39:I39) -> 0 | L39: Своя статья
B40: Итого по блоку | E40: =SUM(E35:E39) -> 516000 | F40: =SUM(F35:F39) -> 577920 | G40: =SUM(G35:G39) -> 647270.4 | H40: =SUM(H35:H39) -> 724942.85 | I40: =SUM(I35:I39) -> 811935.99 | J40: =SUM(J35:J39) -> 3278069.2 | K40: =IFERROR(J40/$J$51,0) -> 0.083084282
B42: БЛОК 5. Разовые затраты и комплаенс
B43: Юридический и комплаенс-аудит (NDPR, POPIA, KICA) | C43: фикс | D43: 15000 | E43: {=IF($D43="","",$D43*INDEX(Допущения!$C$25:$G$30,MATCH($C43,Допущения!$B$25:$B$30,0),1))} -> 15000 | F43: {=IF($D43="","",$D43*INDEX(Допущения!$C$25:$G$30,MATCH($C43,Допущения!$B$25:$B$30,0),2))} -> 15000 | G43: {=IF($D43="","",$D43*INDEX(Допущения!$C$25:$G$30,MATCH($C43,Допущения!$B$25:$B$30,0),3))} -> 15000 | H43: {=IF($D43="","",$D43*INDEX(Допущения!$C$25:$G$30,MATCH($C43,Допущения!$B$25:$B$30,0),4))} -> 15000 | I43: {=IF($D43="","",$D43*INDEX(Допущения!$C$25:$G$30,MATCH($C43,Допущения!$B$25:$B$30,0),5))} -> 15000 | J43: =SUM(E43:I43) -> 75000 | L43: Разовая статья — обнули лишние годы вручную
B44: Пентест и аудит безопасности | C44: инфляция | D44: 10000 | E44: {=IF($D44="","",$D44*INDEX(Допущения!$C$25:$G$30,MATCH($C44,Допущения!$B$25:$B$30,0),1))} -> 10000 | F44: {=IF($D44="","",$D44*INDEX(Допущения!$C$25:$G$30,MATCH($C44,Допущения!$B$25:$B$30,0),2))} -> 10800 | G44: {=IF($D44="","",$D44*INDEX(Допущения!$C$25:$G$30,MATCH($C44,Допущения!$B$25:$B$30,0),3))} -> 11664 | H44: {=IF($D44="","",$D44*INDEX(Допущения!$C$25:$G$30,MATCH($C44,Допущения!$B$25:$B$30,0),4))} -> 12597.12 | I44: {=IF($D44="","",$D44*INDEX(Допущения!$C$25:$G$30,MATCH($C44,Допущения!$B$25:$B$30,0),5))} -> 13604.89 | J44: =SUM(E44:I44) -> 58666.01 | L44: Ежегодно, если mission critical
B45: Миграция данных и интеграции при запуске | C45: фикс | D45: 98000 | E45: {=IF($D45="","",$D45*INDEX(Допущения!$C$25:$G$30,MATCH($C45,Допущения!$B$25:$B$30,0),1))} -> 98000 | F45: {=IF($D45="","",$D45*INDEX(Допущения!$C$25:$G$30,MATCH($C45,Допущения!$B$25:$B$30,0),2))} -> 98000 | G45: {=IF($D45="","",$D45*INDEX(Допущения!$C$25:$G$30,MATCH($C45,Допущения!$B$25:$B$30,0),3))} -> 98000 | H45: {=IF($D45="","",$D45*INDEX(Допущения!$C$25:$G$30,MATCH($C45,Допущения!$B$25:$B$30,0),4))} -> 98000 | I45: {=IF($D45="","",$D45*INDEX(Допущения!$C$25:$G$30,MATCH($C45,Допущения!$B$25:$B$30,0),5))} -> 98000 | J45: =SUM(E45:I45) -> 490000 | L45: Разовая статья
B46: Обучение команды и найм | C46: ФОТ | D46: 0 | E46: {=IF($D46="","",$D46*INDEX(Допущения!$C$25:$G$30,MATCH($C46,Допущения!$B$25:$B$30,0),1))} -> 0 | F46: {=IF($D46="","",$D46*INDEX(Допущения!$C$25:$G$30,MATCH($C46,Допущения!$B$25:$B$30,0),2))} -> 0 | G46: {=IF($D46="","",$D46*INDEX(Допущения!$C$25:$G$30,MATCH($C46,Допущения!$B$25:$B$30,0),3))} -> 0 | H46: {=IF($D46="","",$D46*INDEX(Допущения!$C$25:$G$30,MATCH($C46,Допущения!$B$25:$B$30,0),4))} -> 0 | I46: {=IF($D46="","",$D46*INDEX(Допущения!$C$25:$G$30,MATCH($C46,Допущения!$B$25:$B$30,0),5))} -> 0 | J46: =SUM(E46:I46) -> 0 | L46: Дефицит локальных ИТ-специалистов
...

Sheet TCO-C
B2: TCO на 5 лет — Africa Delivery
B3: Заполняем колонки «Драйвер роста» и «База, $/год (Год 1)». Годы 1–5 считаются автоматически.
B5: Статья затрат | C5: Драйвер роста | D5: База, $/год (Год 1) | E5: Год 1 | F5: Год 2 | G5: Год 3 | H5: Год 4 | I5: Год 5 | J5: Итого 5 лет | K5: Доля | L5: Комментарий / источник
B6: БЛОК 1. Облачная инфраструктура (OpEx)
B7: Compute: ноды / контейнеры / serverless | C7: пользователи | D7: 64800 | E7: {=IF($D7="","",$D7*INDEX(Допущения!$C$25:$G$30,MATCH($C7,Допущения!$B$25:$B$30,0),1))} -> 64800 | F7: {=IF($D7="","",$D7*INDEX(Допущения!$C$25:$G$30,MATCH($C7,Допущения!$B$25:$B$30,0),2))} -> 259200 | G7: {=IF($D7="","",$D7*INDEX(Допущения!$C$25:$G$30,MATCH($C7,Допущения!$B$25:$B$30,0),3))} -> 648000 | H7: {=IF($D7="","",$D7*INDEX(Допущения!$C$25:$G$30,MATCH($C7,Допущения!$B$25:$B$30,0),4))} -> 1080000 | I7: {=IF($D7="","",$D7*INDEX(Допущения!$C$25:$G$30,MATCH($C7,Допущения!$B$25:$B$30,0),5))} -> 1512000 | J7: =SUM(E7:I7) -> 3564000 | L7: AWS af-south-1, оценка по калькулятору
B8: Управляемые БД (PostgreSQL, реплики) | C8: пользователи | D8: 64800 | E8: {=IF($D8="","",$D8*INDEX(Допущения!$C$25:$G$30,MATCH($C8,Допущения!$B$25:$B$30,0),1))} -> 64800 | F8: {=IF($D8="","",$D8*INDEX(Допущения!$C$25:$G$30,MATCH($C8,Допущения!$B$25:$B$30,0),2))} -> 259200 | G8: {=IF($D8="","",$D8*INDEX(Допущения!$C$25:$G$30,MATCH($C8,Допущения!$B$25:$B$30,0),3))} -> 648000 | H8: {=IF($D8="","",$D8*INDEX(Допущения!$C$25:$G$30,MATCH($C8,Допущения!$B$25:$B$30,0),4))} -> 1080000 | I8: {=IF($D8="","",$D8*INDEX(Допущения!$C$25:$G$30,MATCH($C8,Допущения!$B$25:$B$30,0),5))} -> 1512000 | J8: =SUM(E8:I8) -> 3564000 | L8: Managed RDS + read replica
B9: Хранилище объектов и резервные копии | C9: пользователи | D9: 17280 | E9: {=IF($D9="","",$D9*INDEX(Допущения!$C$25:$G$30,MATCH($C9,Допущения!$B$25:$B$30,0),1))} -> 17280 | F9: {=IF($D9="","",$D9*INDEX(Допущения!$C$25:$G$30,MATCH($C9,Допущения!$B$25:$B$30,0),2))} -> 69120 | G9: {=IF($D9="","",$D9*INDEX(Допущения!$C$25:$G$30,MATCH($C9,Допущения!$B$25:$B$30,0),3))} -> 172800 | H9: {=IF($D9="","",$D9*INDEX(Допущения!$C$25:$G$30,MATCH($C9,Допущения!$B$25:$B$30,0),4))} -> 288000 | I9: {=IF($D9="","",$D9*INDEX(Допущения!$C$25:$G$30,MATCH($C9,Допущения!$B$25:$B$30,0),5))} -> 403200 | J9: =SUM(E9:I9) -> 950400 | L9: Фото товаров, 5000 SKU на старте
B10: CDN и исходящий трафик | C10: пользователи | D10: 15120 | E10: {=IF($D10="","",$D10*INDEX(Допущения!$C$25:$G$30,MATCH($C10,Допущения!$B$25:$B$30,0),1))} -> 15120 | F10: {=IF($D10="","",$D10*INDEX(Допущения!$C$25:$G$30,MATCH($C10,Допущения!$B$25:$B$30,0),2))} -> 60480 | G10: {=IF($D10="","",$D10*INDEX(Допущения!$C$25:$G$30,MATCH($C10,Допущения!$B$25:$B$30,0),3))} -> 151200 | H10: {=IF($D10="","",$D10*INDEX(Допущения!$C$25:$G$30,MATCH($C10,Допущения!$B$25:$B$30,0),4))} -> 252000 | I10: {=IF($D10="","",$D10*INDEX(Допущения!$C$25:$G$30,MATCH($C10,Допущения!$B$25:$B$30,0),5))} -> 352800 | J10: =SUM(E10:I10) -> 831600 | L10: 70% трафика — мобильный 3G, картинки WebP
B11: Очереди / стриминг (Kafka, SQS) | C11: пользователи | D11: 0 | E11: {=IF($D11="","",$D11*INDEX(Допущения!$C$25:$G$30,MATCH($C11,Допущения!$B$25:$B$30,0),1))} -> 0 | F11: {=IF($D11="","",$D11*INDEX(Допущения!$C$25:$G$30,MATCH($C11,Допущения!$B$25:$B$30,0),2))} -> 0 | G11: {=IF($D11="","",$D11*INDEX(Допущения!$C$25:$G$30,MATCH($C11,Допущения!$B$25:$B$30,0),3))} -> 0 | H11: {=IF($D11="","",$D11*INDEX(Допущения!$C$25:$G$30,MATCH($C11,Допущения!$B$25:$B$30,0),4))} -> 0 | I11: {=IF($D11="","",$D11*INDEX(Допущения!$C$25:$G$30,MATCH($C11,Допущения!$B$25:$B$30,0),5))} -> 0 | J11: =SUM(E11:I11) -> 0 | L11: Асинхронные заказы и уведомления
B12: Резервный регион / DR | C12: пользователи | D12: 0 | E12: {=IF($D12="","",$D12*INDEX(Допущения!$C$25:$G$30,MATCH($C12,Допущения!$B$25:$B$30,0),1))} -> 0 | F12: {=IF($D12="","",$D12*INDEX(Допущения!$C$25:$G$30,MATCH($C12,Допущения!$B$25:$B$30,0),2))} -> 0 | G12: {=IF($D12="","",$D12*INDEX(Допущения!$C$25:$G$30,MATCH($C12,Допущения!$B$25:$B$30,0),3))} -> 0 | H12: {=IF($D12="","",$D12*INDEX(Допущения!$C$25:$G$30,MATCH($C12,Допущения!$B$25:$B$30,0),4))} -> 0 | I12: {=IF($D12="","",$D12*INDEX(Допущения!$C$25:$G$30,MATCH($C12,Допущения!$B$25:$B$30,0),5))} -> 0 | J12: =SUM(E12:I12) -> 0 | L12: Зависит от выбранной стратегии RTO/RPO
B13: Локальное размещение данных (NDPR, Нигерия) | C13: инфляция | D13: 11152.83 | E13: {=IF($D13="","",$D13*INDEX(Допущения!$C$25:$G$30,MATCH($C13,Допущения!$B$25:$B$30,0),1))} -> 11152.83 | F13: {=IF($D13="","",$D13*INDEX(Допущения!$C$25:$G$30,MATCH($C13,Допущения!$B$25:$B$30,0),2))} -> 12045.056 | G13: {=IF($D13="","",$D13*INDEX(Допущения!$C$25:$G$30,MATCH($C13,Допущения!$B$25:$B$30,0),3))} -> 13008.661 | H13: {=IF($D13="","",$D13*INDEX(Допущения!$C$25:$G$30,MATCH($C13,Допущения!$B$25:$B$30,0),4))} -> 14049.354 | I13: {=IF($D13="","",$D13*INDEX(Допущения!$C$25:$G$30,MATCH($C13,Допущения!$B$25:$B$30,0),5))} -> 15173.302 | J13: =SUM(E13:I13) -> 65429.203 | L13: Локальный провайдер или партнёр — см. ADR №3
C14: фикс | D14: 0 | E14: {=IF($D14="","",$D14*INDEX(Допущения!$C$25:$G$30,MATCH($C14,Допущения!$B$25:$B$30,0),1))} -> 0 | F14: {=IF($D14="","",$D14*INDEX(Допущения!$C$25:$G$30,MATCH($C14,Допущения!$B$25:$B$30,0),2))} -> 0 | G14: {=IF($D14="","",$D14*INDEX(Допущения!$C$25:$G$30,MATCH($C14,Допущения!$B$25:$B$30,0),3))} -> 0 | H14: {=IF($D14="","",$D14*INDEX(Допущения!$C$25:$G$30,MATCH($C14,Допущения!$B$25:$B$30,0),4))} -> 0 | I14: {=IF($D14="","",$D14*INDEX(Допущения!$C$25:$G$30,MATCH($C14,Допущения!$B$25:$B$30,0),5))} -> 0 | J14: =SUM(E14:I14) -> 0 | L14: Своя статья
B15: Итого по блоку | E15: =SUM(E7:E14) -> 173152.83 | F15: =SUM(F7:F14) -> 660045.06 | G15: =SUM(G7:G14) -> 1633008.7 | H15: =SUM(H7:H14) -> 2714049.4 | I15: =SUM(I7:I14) -> 3795173.3 | J15: =SUM(J7:J14) -> 8975429.2 | K15: =IFERROR(J15/$J$51,0) -> 0.17997948
B17: БЛОК 2. Лицензии, SaaS и инструменты
B18: Observability (метрики, логи, трейсинг) | C18: пользователи | D18: 0 | E18: {=IF($D18="","",$D18*INDEX(Допущения!$C$25:$G$30,MATCH($C18,Допущения!$B$25:$B$30,0),1))} -> 0 | F18: {=IF($D18="","",$D18*INDEX(Допущения!$C$25:$G$30,MATCH($C18,Допущения!$B$25:$B$30,0),2))} -> 0 | G18: {=IF($D18="","",$D18*INDEX(Допущения!$C$25:$G$30,MATCH($C18,Допущения!$B$25:$B$30,0),3))} -> 0 | H18: {=IF($D18="","",$D18*INDEX(Допущения!$C$25:$G$30,MATCH($C18,Допущения!$B$25:$B$30,0),4))} -> 0 | I18: {=IF($D18="","",$D18*INDEX(Допущения!$C$25:$G$30,MATCH($C18,Допущения!$B$25:$B$30,0),5))} -> 0 | J18: =SUM(E18:I18) -> 0 | L18: Объём логов растёт с нагрузкой
B19: CI/CD, репозиторий, артефакты | C19: инфляция | D19: 0 | E19: {=IF($D19="","",$D19*INDEX(Допущения!$C$25:$G$30,MATCH($C19,Допущения!$B$25:$B$30,0),1))} -> 0 | F19: {=IF($D19="","",$D19*INDEX(Допущения!$C$25:$G$30,MATCH($C19,Допущения!$B$25:$B$30,0),2))} -> 0 | G19: {=IF($D19="","",$D19*INDEX(Допущения!$C$25:$G$30,MATCH($C19,Допущения!$B$25:$B$30,0),3))} -> 0 | H19: {=IF($D19="","",$D19*INDEX(Допущения!$C$25:$G$30,MATCH($C19,Допущения!$B$25:$B$30,0),4))} -> 0 | I19: {=IF($D19="","",$D19*INDEX(Допущения!$C$25:$G$30,MATCH($C19,Допущения!$B$25:$B$30,0),5))} -> 0 | J19: =SUM(E19:I19) -> 0 | L19: GitHub / GitLab, тарифы на команду
B20: Безопасность: WAF, секреты, антифрод | C20: пользователи | D20: 0 | E20: {=IF($D20="","",$D20*INDEX(Допущения!$C$25:$G$30,MATCH($C20,Допущения!$B$25:$B$30,0),1))} -> 0 | F20: {=IF($D20="","",$D20*INDEX(Допущения!$C$25:$G$30,MATCH($C20,Допущения!$B$25:$B$30,0),2))} -> 0 | G20: {=IF($D20="","",$D20*INDEX(Допущения!$C$25:$G$30,MATCH($C20,Допущения!$B$25:$B$30,0),3))} -> 0 | H20: {=IF($D20="","",$D20*INDEX(Допущения!$C$25:$G$30,MATCH($C20,Допущения!$B$25:$B$30,0),4))} -> 0 | I20: {=IF($D20="","",$D20*INDEX(Допущения!$C$25:$G$30,MATCH($C20,Допущения!$B$25:$B$30,0),5))} -> 0 | J20: =SUM(E20:I20) -> 0 | L20: Мошенничество на ПВЗ — риск из кейса
B21: WhatsApp Business API (подписка) | C21: инфляция | D21: 600 | E21: {=IF($D21="","",$D21*INDEX(Допущения!$C$25:$G$30,MATCH($C21,Допущения!$B$25:$B$30,0),1))} -> 600 | F21: {=IF($D21="","",$D21*INDEX(Допущения!$C$25:$G$30,MATCH($C21,Допущения!$B$25:$B$30,0),2))} -> 648 | G21: {=IF($D21="","",$D21*INDEX(Допущения!$C$25:$G$30,MATCH($C21,Допущения!$B$25:$B$30,0),3))} -> 699.84 | H21: {=IF($D21="","",$D21*INDEX(Допущения!$C$25:$G$30,MATCH($C21,Допущения!$B$25:$B$30,0),4))} -> 755.8272 | I21: {=IF($D21="","",$D21*INDEX(Допущения!$C$25:$G$30,MATCH($C21,Допущения!$B$25:$B$30,0),5))} -> 816.29338 | J21: =SUM(E21:I21) -> 3519.9606 | L21: Канал для продавцов без личного кабинета
B22: Прочее ПО и подписки | C22: инфляция | D22: 167200 | E22: {=IF($D22="","",$D22*INDEX(Допущения!$C$25:$G$30,MATCH($C22,Допущения!$B$25:$B$30,0),1))} -> 167200 | F22: {=IF($D22="","",$D22*INDEX(Допущения!$C$25:$G$30,MATCH($C22,Допущения!$B$25:$B$30,0),2))} -> 180576 | G22: {=IF($D22="","",$D22*INDEX(Допущения!$C$25:$G$30,MATCH($C22,Допущения!$B$25:$B$30,0),3))} -> 195022.08 | H22: {=IF($D22="","",$D22*INDEX(Допущения!$C$25:$G$30,MATCH($C22,Допущения!$B$25:$B$30,0),4))} -> 210623.85 | I22: {=IF($D22="","",$D22*INDEX(Допущения!$C$25:$G$30,MATCH($C22,Допущения!$B$25:$B$30,0),5))} -> 227473.75 | J22: =SUM(E22:I22) -> 980895.68 | L22: Таск-трекер, дизайн, аналитика
C23: фикс | D23: 0 | E23: {=IF($D23="","",$D23*INDEX(Допущения!$C$25:$G$30,MATCH($C23,Допущения!$B$25:$B$30,0),1))} -> 0 | F23: {=IF($D23="","",$D23*INDEX(Допущения!$C$25:$G$30,MATCH($C23,Допущения!$B$25:$B$30,0),2))} -> 0 | G23: {=IF($D23="","",$D23*INDEX(Допущения!$C$25:$G$30,MATCH($C23,Допущения!$B$25:$B$30,0),3))} -> 0 | H23: {=IF($D23="","",$D23*INDEX(Допущения!$C$25:$G$30,MATCH($C23,Допущения!$B$25:$B$30,0),4))} -> 0 | I23: {=IF($D23="","",$D23*INDEX(Допущения!$C$25:$G$30,MATCH($C23,Допущения!$B$25:$B$30,0),5))} -> 0 | J23: =SUM(E23:I23) -> 0 | L23: Своя статья
B24: Итого по блоку | E24: =SUM(E18:E23) -> 167800 | F24: =SUM(F18:F23) -> 181224 | G24: =SUM(G18:G23) -> 195721.92 | H24: =SUM(H18:H23) -> 211379.67 | I24: =SUM(I18:I23) -> 228290.05 | J24: =SUM(J18:J23) -> 984415.64 | K24: =IFERROR(J24/$J$51,0) -> 0.01973996
B26: БЛОК 3. Транзакционные расходы (Buy / Partner)
B27: Комиссии платёжных провайдеров | C27: GMV | D27: 137500 | E27: {=IF($D27="","",$D27*INDEX(Допущения!$C$25:$G$30,MATCH($C27,Допущения!$B$25:$B$30,0),1))} -> 137500 | F27: {=IF($D27="","",$D27*INDEX(Допущения!$C$25:$G$30,MATCH($C27,Допущения!$B$25:$B$30,0),2))} -> 858000 | G27: {=IF($D27="","",$D27*INDEX(Допущения!$C$25:$G$30,MATCH($C27,Допущения!$B$25:$B$30,0),3))} -> 2970000 | H27: {=IF($D27="","",$D27*INDEX(Допущения!$C$25:$G$30,MATCH($C27,Допущения!$B$25:$B$30,0),4))} -> 6160000 | I27: {=IF($D27="","",$D27*INDEX(Допущения!$C$25:$G$30,MATCH($C27,Допущения!$B$25:$B$30,0),5))} -> 9570000 | J27: =SUM(E27:I27) -> 19695500 | L27: ≈3% от GMV: M-Pesa (Кения), Flutterwave / Paystack (Нигерия)
B28: SMS-уведомления | C28: заказы | D28: 18000 | E28: {=IF($D28="","",$D28*INDEX(Допущения!$C$25:$G$30,MATCH($C28,Допущения!$B$25:$B$30,0),1))} -> 18000 | F28: {=IF($D28="","",$D28*INDEX(Допущения!$C$25:$G$30,MATCH($C28,Допущения!$B$25:$B$30,0),2))} -> 108000 | G28: {=IF($D28="","",$D28*INDEX(Допущения!$C$25:$G$30,MATCH($C28,Допущения!$B$25:$B$30,0),3))} -> 360000 | H28: {=IF($D28="","",$D28*INDEX(Допущения!$C$25:$G$30,MATCH($C28,Допущения!$B$25:$B$30,0),4))} -> 720000 | I28: {=IF($D28="","",$D28*INDEX(Допущения!$C$25:$G$30,MATCH($C28,Допущения!$B$25:$B$30,0),5))} -> 1080000 | J28: =SUM(E28:I28) -> 2286000 | L28: ≈$0,04 за SMS × заказы
B29: WhatsApp-сообщения (за диалог) | C29: заказы | D29: 7200 | E29: {=IF($D29="","",$D29*INDEX(Допущения!$C$25:$G$30,MATCH($C29,Допущения!$B$25:$B$30,0),1))} -> 7200 | F29: {=IF($D29="","",$D29*INDEX(Допущения!$C$25:$G$30,MATCH($C29,Допущения!$B$25:$B$30,0),2))} -> 43200 | G29: {=IF($D29="","",$D29*INDEX(Допущения!$C$25:$G$30,MATCH($C29,Допущения!$B$25:$B$30,0),3))} -> 144000 | H29: {=IF($D29="","",$D29*INDEX(Допущения!$C$25:$G$30,MATCH($C29,Допущения!$B$25:$B$30,0),4))} -> 288000 | I29: {=IF($D29="","",$D29*INDEX(Допущения!$C$25:$G$30,MATCH($C29,Допущения!$B$25:$B$30,0),5))} -> 432000 | J29: =SUM(E29:I29) -> 914400 | L29: Тариф Meta за conversation
B30: Логистика: интеграции и комиссии партнёров | C30: заказы | D30: =Допущения!C8*0.1 -> 30000 | E30: {=IF($D30="","",$D30*INDEX(Допущения!$C$25:$G$30,MATCH($C30,Допущения!$B$25:$B$30,0),1))} -> 30000 | F30: {=IF($D30="","",$D30*INDEX(Допущения!$C$25:$G$30,MATCH($C30,Допущения!$B$25:$B$30,0),2))} -> 180000 | G30: {=IF($D30="","",$D30*INDEX(Допущения!$C$25:$G$30,MATCH($C30,Допущения!$B$25:$B$30,0),3))} -> 600000 | H30: {=IF($D30="","",$D30*INDEX(Допущения!$C$25:$G$30,MATCH($C30,Допущения!$B$25:$B$30,0),4))} -> 1200000 | I30: {=IF($D30="","",$D30*INDEX(Допущения!$C$25:$G$30,MATCH($C30,Допущения!$B$25:$B$30,0),5))} -> 1800000 | J30: =SUM(E30:I30) -> 3810000 | L30: Sendbox (Нигерия), Sendy (Кения)
C31: фикс | D31: 0 | E31: {=IF($D31="","",$D31*INDEX(Допущения!$C$25:$G$30,MATCH($C31,Допущения!$B$25:$B$30,0),1))} -> 0 | F31: {=IF($D31="","",$D31*INDEX(Допущения!$C$25:$G$30,MATCH($C31,Допущения!$B$25:$B$30,0),2))} -> 0 | G31: {=IF($D31="","",$D31*INDEX(Допущения!$C$25:$G$30,MATCH($C31,Допущения!$B$25:$B$30,0),3))} -> 0 | H31: {=IF($D31="","",$D31*INDEX(Допущения!$C$25:$G$30,MATCH($C31,Допущения!$B$25:$B$30,0),4))} -> 0 | I31: {=IF($D31="","",$D31*INDEX(Допущения!$C$25:$G$30,MATCH($C31,Допущения!$B$25:$B$30,0),5))} -> 0 | J31: =SUM(E31:I31) -> 0 | L31: Своя статья
B32: Итого по блоку | E32: =SUM(E27:E31) -> 192700 | F32: =SUM(F27:F31) -> 1189200 | G32: =SUM(G27:G31) -> 4074000 | H32: =SUM(H27:H31) -> 8368000 | I32: =SUM(I27:I31) -> 12882000 | J32: =SUM(J27:J31) -> 26705900 | K32: =IFERROR(J32/$J$51,0) -> 0.53551912
B34: БЛОК 4. Команда (ФОТ)
